Workbook

Sheet README
A1: FIFA 2026 Tournament Progress Map - live ready v3
A3: Exact teams
A4: Results so far | B4: Completed matches through 15 Jun 2026 are filled in the Match Results score cells.
A5: Future updates | B5: Enter future scores in yellow score cells in Match Results or use the live HTML file. Standings, best third-place ranking, knockout entrants and bracket winners update automatically.
A6: Tournament map | B6: The visual bracket uses official match IDs M73 to M104 and has been ordered to follow the official knockout path.
A7: Yellow cells | B7: Editable inputs: future match scores and bracket winner overrides.
A8: Green cells | B8: Formula outputs that should not be edited.
A9: Third-place logic | B9: The Setup sheet uses the FIFA Annex C 495-row matrix to place the eight best third-place teams into the Round of 32.
A10: Tie breaker note | B10: The spreadsheet ranks teams by points, goal difference, goals scored and seed as a final fallback. FIFA may use additional disciplinary or ranking criteria for unresolved ties.
A11: Live HTML | B11: The HTML dashboard tries to refresh from the ESPN scoreboard endpoint on load and every five minutes. Browser CORS restrictions may require manual refresh or manual entry.
A12: Updated | B12: 16 Jun 2026, 15:30 UTC
A13: Official schedule | B13: https://www.fifa.com/en/tournaments/mens/worldcup/canadamexicousa2026/articles/match-schedule-fixtures-results-teams-stadiums
A14: Results source | B14: https://www.espn.com/soccer/story/_/id/48939282/2026-fifa-world-cup-fixtures-results-match-schedule-group-stage-knockout-rounds-bracket
A15: Regulations source | B15: https://cdn.thuvienphapluat.vn/phap-luat/2022-2/TTKP/FWC26-regulations.pdf
... A26: Excel note | B26: Excel flag images are embedded visuals. The tournament progression formulas remain in the workbook.

Sheet Group Stage
A1: Group Stage Tracker - formula driven from Match Results
A2: Edit scores in Match Results. Rankings update automatically. Status remains Pending or In play until all six group matches are final.
A3: Group | B3: Seed | C3: Team | D3: W | E3: D | F3: L | G3: GF | H3: GA | I3: MP | J3: GD | K3: Pts | L3: Group Rank | M3: 3rd Rank | N3: Status | O3: Team with real flag
A4: A | B4: 1 | C4: Mexico | D4: =COUNTIFS('Match Results'!$C$4:$C$75,$A4,'Match Results'!$I$4:$I$75,$C4) | E4: =COUNTIFS('Match Results'!$C$4:$C$75,$A4,'Match Results'!$D$4:$D$75,$C4,'Match Results'!$I$4:$I$75,"Draw")+COUNTIFS('Match Results'!$C$4:$C$75,$A4,'Match Results'!$G$4:$G$75,$C4,'Match Results'!$I$4:$I$75,"Draw") | F4: =I4-D4-E4 | G4: =SUMIFS('Match Results'!$E$4:$E$75,'Match Results'!$C$4:$C$75,$A4,'Match Results'!$D$4:$D$75,$C4)+SUMIFS('Match Results'!$F$4:$F$75,'Match Results'!$C$4:$C$75,$A4,'Match Results'!$G$4:$G$75,$C4) | H4: =SUMIFS('Match Results'!$F$4:$F$75,'Match Results'!$C$4:$C$75,$A4,'Match Results'!$D$4:$D$75,$C4)+SUMIFS('Match Results'!$E$4:$E$75,'Match Results'!$C$4:$C$75,$A4,'Match Results'!$G$4:$G$75,$C4) | I4: =COUNTIFS('Match Results'!$C$4:$C$75,$A4,'Match Results'!$D$4:$D$75,$C4,'Match Results'!$H$4:$H$75,"Final")+COUNTIFS('Match Results'!$C$4:$C$75,$A4,'Match Results'!$G$4:$G$75,$C4,'Match Results'!$H$4:$H$75,"Final") | J4: =G4-H4 | K4: =D4*3+E4 | L4: =1+SUMPRODUCT(($A$4:$A$51=$A4)*(($K$4:$K$51>K4)+(($K$4:$K$51=K4)*($J$4:$J$51>J4))+(($K$4:$K$51=K4)*($J$4:$J$51=J4)*($G$4:$G$51>G4))+(($K$4:$K$51=K4)*($J$4:$J$51=J4)*($G$4:$G$51=G4)*($B$4:$B$51<B4)))) | M4: =IF(L4=3,1+SUMPRODUCT(($L$4:$L$51=3)*(($K$4:$K$51>K4)+(($K$4:$K$51=K4)*($J$4:$J$51>J4))+(($K$4:$K$51=K4)*($J$4:$J$51=J4)*($G$4:$G$51>G4))+(($K$4:$K$51=K4)*($J$4:$J$51=J4)*($G$4:$G$51=G4)*(ROW($A$4:$A$51)<ROW(A4))))),"") | N4: =IF(COUNTIFS('Match Results'!$C$4:$C$75,$A4,'Match Results'!$H$4:$H$75,"Final")<6,IF(I4=0,"Pending","In play"),IF(L4<=2,"Qualified",IF(AND(L4=3,M4<=8),"Qualified best 3rd","Eliminated"))) | O4: =C4
A5: A | B5: 2 | C5: South Africa | D5: =COUNTIFS('Match Results'!$C$4:$C$75,$A5,'Match Results'!$I$4:$I$75,$C5) | E5: =COUNTIFS('Match Results'!$C$4:$C$75,$A5,'Match Results'!$D$4:$D$75,$C5,'Match Results'!$I$4:$I$75,"Draw")+COUNTIFS('Match Results'!$C$4:$C$75,$A5,'Match Results'!$G$4:$G$75,$C5,'Match Results'!$I$4:$I$75,"Draw") | F5: =I5-D5-E5 | G5: =SUMIFS('Match Results'!$E$4:$E$75,'Match Results'!$C$4:$C$75,$A5,'Match Results'!$D$4:$D$75,$C5)+SUMIFS('Match Results'!$F$4:$F$75,'Match Results'!$C$4:$C$75,$A5,'Match Results'!$G$4:$G$75,$C5) | H5: =SUMIFS('Match Results'!$F$4:$F$75,'Match Results'!$C$4:$C$75,$A5,'Match Results'!$D$4:$D$75,$C5)+SUMIFS('Match Results'!$E$4:$E$75,'Match Results'!$C$4:$C$75,$A5,'Match Results'!$G$4:$G$75,$C5) | I5: =COUNTIFS('Match Results'!$C$4:$C$75,$A5,'Match Results'!$D$4:$D$75,$C5,'Match Results'!$H$4:$H$75,"Final")+COUNTIFS('Match Results'!$C$4:$C$75,$A5,'Match Results'!$G$4:$G$75,$C5,'Match Results'!$H$4:$H$75,"Final") | J5: =G5-H5 | K5: =D5*3+E5 | L5: =1+SUMPRODUCT(($A$4:$A$51=$A5)*(($K$4:$K$51>K5)+(($K$4:$K$51=K5)*($J$4:$J$51>J5))+(($K$4:$K$51=K5)*($J$4:$J$51=J5)*($G$4:$G$51>G5))+(($K$4:$K$51=K5)*($J$4:$J$51=J5)*($G$4:$G$51=G5)*($B$4:$B$51<B5)))) | M5: =IF(L5=3,1+SUMPRODUCT(($L$4:$L$51=3)*(($K$4:$K$51>K5)+(($K$4:$K$51=K5)*($J$4:$J$51>J5))+(($K$4:$K$51=K5)*($J$4:$J$51=J5)*($G$4:$G$51>G5))+(($K$4:$K$51=K5)*($J$4:$J$51=J5)*($G$4:$G$51=G5)*(ROW($A$4:$A$51)<ROW(A5))))),"") | N5: =IF(COUNTIFS('Match Results'!$C$4:$C$75,$A5,'Match Results'!$H$4:$H$75,"Final")<6,IF(I5=0,"Pending","In play"),IF(L5<=2,"Qualified",IF(AND(L5=3,M5<=8),"Qualified best 3rd","Eliminated"))) | O5: =C5
A6: A | B6: 3 | C6: Korea Republic | D6: =COUNTIFS('Match Results'!$C$4:$C$75,$A6,'Match Results'!$I$4:$I$75,$C6) | E6: =COUNTIFS('Match Results'!$C$4:$C$75,$A6,'Match Results'!$D$4:$D$75,$C6,'Match Results'!$I$4:$I$75,"Draw")+COUNTIFS('Match Results'!$C$4:$C$75,$A6,'Match Results'!$G$4:$G$75,$C6,'Match Results'!$I$4:$I$75,"Draw") | F6: =I6-D6-E6 | G6: =SUMIFS('Match Results'!$E$4:$E$75,'Match Results'!$C$4:$C$75,$A6,'Match Results'!$D$4:$D$75,$C6)+SUMIFS('Match Results'!$F$4:$F$75,'Match Results'!$C$4:$C$75,$A6,'Match Results'!$G$4:$G$75,$C6) | H6: =SUMIFS('Match Results'!$F$4:$F$75,'Match Results'!$C$4:$C$75,$A6,'Match Results'!$D$4:$D$75,$C6)+SUMIFS('Match Results'!$E$4:$E$75,'Match Results'!$C$4:$C$75,$A6,'Match Results'!$G$4:$G$75,$C6) | I6: =COUNTIFS('Match Results'!$C$4:$C$75,$A6,'Match Results'!$D$4:$D$75,$C6,'Match Results'!$H$4:$H$75,"Final")+COUNTIFS('Match Results'!$C$4:$C$75,$A6,'Match Results'!$G$4:$G$75,$C6,'Match Results'!$H$4:$H$75,"Final") | J6: =G6-H6 | K6: =D6*3+E6 | L6: =1+SUMPRODUCT(($A$4:$A$51=$A6)*(($K$4:$K$51>K6)+(($K$4:$K$51=K6)*($J$4:$J$51>J6))+(($K$4:$K$51=K6)*($J$4:$J$51=J6)*($G$4:$G$51>G6))+(($K$4:$K$51=K6)*($J$4:$J$51=J6)*($G$4:$G$51=G6)*($B$4:$B$51<B6)))) | M6: =IF(L6=3,1+SUMPRODUCT(($L$4:$L$51=3)*(($K$4:$K$51>K6)+(($K$4:$K$51=K6)*($J$4:$J$51>J6))+(($K$4:$K$51=K6)*($J$4:$J$51=J6)*($G$4:$G$51>G6))+(($K$4:$K$51=K6)*($J$4:$J$51=J6)*($G$4:$G$51=G6)*(ROW($A$4:$A$51)<ROW(A6))))),"") | N6: =IF(COUNTIFS('Match Results'!$C$4:$C$75,$A6,'Match Results'!$H$4:$H$75,"Final")<6,IF(I6=0,"Pending","In play"),IF(L6<=2,"Qualified",IF(AND(L6=3,M6<=8),"Qualified best 3rd","Eliminated"))) | O6: =C6
A7: A | B7: 4 | C7: Czechia | D7: =COUNTIFS('Match Results'!$C$4:$C$75,$A7,'Match Results'!$I$4:$I$75,$C7) | E7: =COUNTIFS('Match Results'!$C$4:$C$75,$A7,'Match Results'!$D$4:$D$75,$C7,'Match Results'!$I$4:$I$75,"Draw")+COUNTIFS('Match Results'!$C$4:$C$75,$A7,'Match Results'!$G$4:$G$75,$C7,'Match Results'!$I$4:$I$75,"Draw") | F7: =I7-D7-E7 | G7: =SUMIFS('Match Results'!$E$4:$E$75,'Match Results'!$C$4:$C$75,$A7,'Match Results'!$D$4:$D$75,$C7)+SUMIFS('Match Results'!$F$4:$F$75,'Match Results'!$C$4:$C$75,$A7,'Match Results'!$G$4:$G$75,$C7) | H7: =SUMIFS('Match Results'!$F$4:$F$75,'Match Results'!$C$4:$C$75,$A7,'Match Results'!$D$4:$D$75,$C7)+SUMIFS('Match Results'!$E$4:$E$75,'Match Results'!$C$4:$C$75,$A7,'Match Results'!$G$4:$G$75,$C7) | I7: =COUNTIFS('Match Results'!$C$4:$C$75,$A7,'Match Results'!$D$4:$D$75,$C7,'Match Results'!$H$4:$H$75,"Final")+COUNTIFS('Match Results'!$C$4:$C$75,$A7,'Match Results'!$G$4:$G$75,$C7,'Match Results'!$H$4:$H$75,"Final") | J7: =G7-H7 | K7: =D7*3+E7 | L7: =1+SUMPRODUCT(($A$4:$A$51=$A7)*(($K$4:$K$51>K7)+(($K$4:$K$51=K7)*($J$4:$J$51>J7))+(($K$4:$K$51=K7)*($J$4:$J$51=J7)*($G$4:$G$51>G7))+(($K$4:$K$51=K7)*($J$4:$J$51=J7)*($G$4:$G$51=G7)*($B$4:$B$51<B7)))) | M7: =IF(L7=3,1+SUMPRODUCT(($L$4:$L$51=3)*(($K$4:$K$51>K7)+(($K$4:$K$51=K7)*($J$4:$J$51>J7))+(($K$4:$K$51=K7)*($J$4:$J$51=J7)*($G$4:$G$51>G7))+(($K$4:$K$51=K7)*($J$4:$J$51=J7)*($G$4:$G$51=G7)*(ROW($A$4:$A$51)<ROW(A7))))),"") | N7: =IF(COUNTIFS('Match Results'!$C$4:$C$75,$A7,'Match Results'!$H$4:$H$75,"Final")<6,IF(I7=0,"Pending","In play"),IF(L7<=2,"Qualified",IF(AND(L7=3,M7<=8),"Qualified best 3rd","Eliminated"))) | O7: =C7
A8: B | B8: 1 | C8: Canada | D8: =COUNTIFS('Match Results'!$C$4:$C$75,$A8,'Match Results'!$I$4:$I$75,$C8) | E8: =COUNTIFS('Match Results'!$C$4:$C$75,$A8,'Match Results'!$D$4:$D$75,$C8,'Match Results'!$I$4:$I$75,"Draw")+COUNTIFS('Match Results'!$C$4:$C$75,$A8,'Match Results'!$G$4:$G$75,$C8,'Match Results'!$I$4:$I$75,"Draw") | F8: =I8-D8-E8 | G8: =SUMIFS('Match Results'!$E$4:$E$75,'Match Results'!$C$4:$C$75,$A8,'Match Results'!$D$4:$D$75,$C8)+SUMIFS('Match Results'!$F$4:$F$75,'Match Results'!$C$4:$C$75,$A8,'Match Results'!$G$4:$G$75,$C8) | H8: =SUMIFS('Match Results'!$F$4:$F$75,'Match Results'!$C$4:$C$75,$A8,'Match Results'!$D$4:$D$75,$C8)+SUMIFS('Match Results'!$E$4:$E$75,'Match Results'!$C$4:$C$75,$A8,'Match Results'!$G$4:$G$75,$C8) | I8: =COUNTIFS('Match Results'!$C$4:$C$75,$A8,'Match Results'!$D$4:$D$75,$C8,'Match Results'!$H$4:$H$75,"Final")+COUNTIFS('Match Results'!$C$4:$C$75,$A8,'Match Results'!$G$4:$G$75,$C8,'Match Results'!$H$4:$H$75,"Final") | J8: =G8-H8 | K8: =D8*3+E8 | L8: =1+SUMPRODUCT(($A$4:$A$51=$A8)*(($K$4:$K$51>K8)+(($K$4:$K$51=K8)*($J$4:$J$51>J8))+(($K$4:$K$51=K8)*($J$4:$J$51=J8)*($G$4:$G$51>G8))+(($K$4:$K$51=K8)*($J$4:$J$51=J8)*($G$4:$G$51=G8)*($B$4:$B$51<B8)))) | M8: =IF(L8=3,1+SUMPRODUCT(($L$4:$L$51=3)*(($K$4:$K$51>K8)+(($K$4:$K$51=K8)*($J$4:$J$51>J8))+(($K$4:$K$51=K8)*($J$4:$J$51=J8)*($G$4:$G$51>G8))+(($K$4:$K$51=K8)*($J$4:$J$51=J8)*($G$4:$G$51=G8)*(ROW($A$4:$A$51)<ROW(A8))))),"") | N8: =IF(COUNTIFS('Match Results'!$C$4:$C$75,$A8,'Match Results'!$H$4:$H$75,"Final")<6,IF(I8=0,"Pending","In play"),IF(L8<=2,"Qualified",IF(AND(L8=3,M8<=8),"Qualified best 3rd","Eliminated"))) | O8: =C8
A9: B | B9: 2 | C9: Bosnia and Herzegovina | D9: =COUNTIFS('Match Results'!$C$4:$C$75,$A9,'Match Results'!$I$4:$I$75,$C9) | E9: =COUNTIFS('Match Results'!$C$4:$C$75,$A9,'Match Results'!$D$4:$D$75,$C9,'Match Results'!$I$4:$I$75,"Draw")+COUNTIFS('Match Results'!$C$4:$C$75,$A9,'Match Results'!$G$4:$G$75,$C9,'Match Results'!$I$4:$I$75,"Draw") | F9: =I9-D9-E9 | G9: =SUMIFS('Match Results'!$E$4:$E$75,'Match Results'!$C$4:$C$75,$A9,'Match Results'!$D$4:$D$75,$C9)+SUMIFS('Match Results'!$F$4:$F$75,'Match Results'!$C$4:$C$75,$A9,'Match Results'!$G$4:$G$75,$C9) | H9: =SUMIFS('Match Results'!$F$4:$F$75,'Match Results'!$C$4:$C$75,$A9,'Match Results'!$D$4:$D$75,$C9)+SUMIFS('Match Results'!$E$4:$E$75,'Match Results'!$C$4:$C$75,$A9,'Match Results'!$G$4:$G$75,$C9) | I9: =COUNTIFS('Match Results'!$C$4:$C$75,$A9,'Match Results'!$D$4:$D$75,$C9,'Match Results'!$H$4:$H$75,"Final")+COUNTIFS('Match Results'!$C$4:$C$75,$A9,'Match Results'!$G$4:$G$75,$C9,'Match Results'!$H$4:$H$75,"Final") | J9: =G9-H9 | K9: =D9*3+E9 | L9: =1+SUMPRODUCT(($A$4:$A$51=$A9)*(($K$4:$K$51>K9)+(($K$4:$K$51=K9)*($J$4:$J$51>J9))+(($K$4:$K$51=K9)*($J$4:$J$51=J9)*($G$4:$G$51>G9))+(($K$4:$K$51=K9)*($J$4:$J$51=J9)*($G$4:$G$51=G9)*($B$4:$B$51<B9)))) | M9: =IF(L9=3,1+SUMPRODUCT(($L$4:$L$51=3)*(($K$4:$K$51>K9)+(($K$4:$K$51=K9)*($J$4:$J$51>J9))+(($K$4:$K$51=K9)*($J$4:$J$51=J9)*($G$4:$G$51>G9))+(($K$4:$K$51=K9)*($J$4:$J$51=J9)*($G$4:$G$51=G9)*(ROW($A$4:$A$51)<ROW(A9))))),"") | N9: =IF(COUNTIFS('Match Results'!$C$4:$C$75,$A9,'Match Results'!$H$4:$H$75,"Final")<6,IF(I9=0,"Pending","In play"),IF(L9<=2,"Qualified",IF(AND(L9=3,M9<=8),"Qualified best 3rd","Eliminated"))) | O9: =C9
A10: B | B10: 3 | C10: Switzerland | D10: =COUNTIFS('Match Results'!$C$4:$C$75,$A10,'Match Results'!$I$4:$I$75,$C10) | E10: =COUNTIFS('Match Results'!$C$4:$C$75,$A10,'Match Results'!$D$4:$D$75,$C10,'Match Results'!$I$4:$I$75,"Draw")+COUNTIFS('Match Results'!$C$4:$C$75,$A10,'Match Results'!$G$4:$G$75,$C10,'Match Results'!$I$4:$I$75,"Draw") | F10: =I10-D10-E10 | G10: =SUMIFS('Match Results'!$E$4:$E$75,'Match Results'!$C$4:$C$75,$A10,'Match Results'!$D$4:$D$75,$C10)+SUMIFS('Match Results'!$F$4:$F$75,'Match Results'!$C$4:$C$75,$A10,'Match Results'!$G$4:$G$75,$C10) | H10: =SUMIFS('Match Results'!$F$4:$F$75,'Match Results'!$C$4:$C$75,$A10,'Match Results'!$D$4:$D$75,$C10)+SUMIFS('Match Results'!$E$4:$E$75,'Match Results'!$C$4:$C$75,$A10,'Match Results'!$G$4:$G$75,$C10) | I10: =COUNTIFS('Match Results'!$C$4:$C$75,$A10,'Match Results'!$D$4:$D$75,$C10,'Match Results'!$H$4:$H$75,"Final")+COUNTIFS('Match Results'!$C$4:$C$75,$A10,'Match Results'!$G$4:$G$75,$C10,'Match Results'!$H$4:$H$75,"Final") | J10: =G10-H10 | K10: =D10*3+E10 | L10: =1+SUMPRODUCT(($A$4:$A$51=$A10)*(($K$4:$K$51>K10)+(($K$4:$K$51=K10)*($J$4:$J$51>J10))+(($K$4:$K$51=K10)*($J$4:$J$51=J10)*($G$4:$G$51>G10))+(($K$4:$K$51=K10)*($J$4:$J$51=J10)*($G$4:$G$51=G10)*($B$4:$B$51<B10)))) | M10: =IF(L10=3,1+SUMPRODUCT(($L$4:$L$51=3)*(($K$4:$K$51>K10)+(($K$4:$K$51=K10)*($J$4:$J$51>J10))+(($K$4:$K$51=K10)*($J$4:$J$51=J10)*($G$4:$G$51>G10))+(($K$4:$K$51=K10)*($J$4:$J$51=J10)*($G$4:$G$51=G10)*(ROW($A$4:$A$51)<ROW(A10))))),"") | N10: =IF(COUNTIFS('Match Results'!$C$4:$C$75,$A10,'Match Results'!$H$4:$H$75,"Final")<6,IF(I10=0,"Pending","In play"),IF(L10<=2,"Qualified",IF(AND(L10=3,M10<=8),"Qualified best 3rd","Eliminated"))) | O10: =C10
A11: B | B11: 4 | C11: Qatar | D11: =COUNTIFS('Match Results'!$C$4:$C$75,$A11,'Match Results'!$I$4:$I$75,$C11) | E11: =COUNTIFS('Match Results'!$C$4:$C$75,$A11,'Match Results'!$D$4:$D$75,$C11,'Match Results'!$I$4:$I$75,"Draw")+COUNTIFS('Match Results'!$C$4:$C$75,$A11,'Match Results'!$G$4:$G$75,$C11,'Match Results'!$I$4:$I$75,"Draw") | F11: =I11-D11-E11 | G11: =SUMIFS('Match Results'!$E$4:$E$75,'Match Results'!$C$4:$C$75,$A11,'Match Results'!$D$4:$D$75,$C11)+SUMIFS('Match Results'!$F$4:$F$75,'Match Results'!$C$4:$C$75,$A11,'Match Results'!$G$4:$G$75,$C11) | H11: =SUMIFS('Match Results'!$F$4:$F$75,'Match Results'!$C$4:$C$75,$A11,'Match Results'!$D$4:$D$75,$C11)+SUMIFS('Match Results'!$E$4:$E$75,'Match Results'!$C$4:$C$75,$A11,'Match Results'!$G$4:$G$75,$C11) | I11: =COUNTIFS('Match Results'!$C$4:$C$75,$A11,'Match Results'!$D$4:$D$75,$C11,'Match Results'!$H$4:$H$75,"Final")+COUNTIFS('Match Results'!$C$4:$C$75,$A11,'Match Results'!$G$4:$G$75,$C11,'Match Results'!$H$4:$H$75,"Final") | J11: =G11-H11 | K11: =D11*3+E11 | L11: =1+SUMPRODUCT(($A$4:$A$51=$A11)*(($K$4:$K$51>K11)+(($K$4:$K$51=K11)*($J$4:$J$51>J11))+(($K$4:$K$51=K11)*($J$4:$J$51=J11)*($G$4:$G$51>G11))+(($K$4:$K$51=K11)*($J$4:$J$51=J11)*($G$4:$G$51=G11)*($B$4:$B$51<B11)))) | M11: =IF(L11=3,1+SUMPRODUCT(($L$4:$L$51=3)*(($K$4:$K$51>K11)+(($K$4:$K$51=K11)*($J$4:$J$51>J11))+(($K$4:$K$51=K11)*($J$4:$J$51=J11)*($G$4:$G$51>G11))+(($K$4:$K$51=K11)*($J$4:$J$51=J11)*($G$4:$G$51=G11)*(ROW($A$4:$A$51)<ROW(A11))))),"") | N11: =IF(COUNTIFS('Match Results'!$C$4:$C$75,$A11,'Match Results'!$H$4:$H$75,"Final")<6,IF(I11=0,"Pending","In play"),IF(L11<=2,"Qualified",IF(AND(L11=3,M11<=8),"Qualified best 3rd","Eliminated"))) | O11: =C11
A12: C | B12: 1 | C12: Brazil | D12: =COUNTIFS('Match Results'!$C$4:$C$75,$A12,'Match Results'!$I$4:$I$75,$C12) | E12: =COUNTIFS('Match Results'!$C$4:$C$75,$A12,'Match Results'!$D$4:$D$75,$C12,'Match Results'!$I$4:$I$75,"Draw")+COUNTIFS('Match Results'!$C$4:$C$75,$A12,'Match Results'!$G$4:$G$75,$C12,'Match Results'!$I$4:$I$75,"Draw") | F12: =I12-D12-E12 | G12: =SUMIFS('Match Results'!$E$4:$E$75,'Match Results'!$C$4:$C$75,$A12,'Match Results'!$D$4:$D$75,$C12)+SUMIFS('Match Results'!$F$4:$F$75,'Match Results'!$C$4:$C$75,$A12,'Match Results'!$G$4:$G$75,$C12) | H12: =SUMIFS('Match Results'!$F$4:$F$75,'Match Results'!$C$4:$C$75,$A12,'Match Results'!$D$4:$D$75,$C12)+SUMIFS('Match Results'!$E$4:$E$75,'Match Results'!$C$4:$C$75,$A12,'Match Results'!$G$4:$G$75,$C12) | I12: =COUNTIFS('Match Results'!$C$4:$C$75,$A12,'Match Results'!$D$4:$D$75,$C12,'Match Results'!$H$4:$H$75,"Final")+COUNTIFS('Match Results'!$C$4:$C$75,$A12,'Match Results'!$G$4:$G$75,$C12,'Match Results'!$H$4:$H$75,"Final") | J12: =G12-H12 | K12: =D12*3+E12 | L12: =1+SUMPRODUCT(($A$4:$A$51=$A12)*(($K$4:$K$51>K12)+(($K$4:$K$51=K12)*($J$4:$J$51>J12))+(($K$4:$K$51=K12)*($J$4:$J$51=J12)*($G$4:$G$51>G12))+(($K$4:$K$51=K12)*($J$4:$J$51=J12)*($G$4:$G$51=G12)*($B$4:$B$51<B12)))) | M12: =IF(L12=3,1+SUMPRODUCT(($L$4:$L$51=3)*(($K$4:$K$51>K12)+(($K$4:$K$51=K12)*($J$4:$J$51>J12))+(($K$4:$K$51=K12)*($J$4:$J$51=J12)*($G$4:$G$51>G12))+(($K$4:$K$51=K12)*($J$4:$J$51=J12)*($G$4:$G$51=G12)*(ROW($A$4:$A$51)<ROW(A12))))),"") | N12: =IF(COUNTIFS('Match Results'!$C$4:$C$75,$A12,'Match Results'!$H$4:$H$75,"Final")<6,IF(I12=0,"Pending","In play"),IF(L12<=2,"Qualified",IF(AND(L12=3,M12<=8),"Qualified best 3rd","Eliminated"))) | O12: =C12
A13: C | B13: 2 | C13: Morocco | D13: =COUNTIFS('Match Results'!$C$4:$C$75,$A13,'Match Results'!$I$4:$I$75,$C13) | E13: =COUNTIFS('Match Results'!$C$4:$C$75,$A13,'Match Results'!$D$4:$D$75,$C13,'Match Results'!$I$4:$I$75,"Draw")+COUNTIFS('Match Results'!$C$4:$C$75,$A13,'Match Results'!$G$4:$G$75,$C13,'Match Results'!$I$4:$I$75,"Draw") | F13: =I13-D13-E13 | G13: =SUMIFS('Match Results'!$E$4:$E$75,'Match Results'!$C$4:$C$75,$A13,'Match Results'!$D$4:$D$75,$C13)+SUMIFS('Match Results'!$F$4:$F$75,'Match Results'!$C$4:$C$75,$A13,'Match Results'!$G$4:$G$75,$C13) | H13: =SUMIFS('Match Results'!$F$4:$F$75,'Match Results'!$C$4:$C$75,$A13,'Match Results'!$D$4:$D$75,$C13)+SUMIFS('Match Results'!$E$4:$E$75,'Match Results'!$C$4:$C$75,$A13,'Match Results'!$G$4:$G$75,$C13) | I13: =COUNTIFS('Match Results'!$C$4:$C$75,$A13,'Match Results'!$D$4:$D$75,$C13,'Match Results'!$H$4:$H$75,"Final")+COUNTIFS('Match Results'!$C$4:$C$75,$A13,'Match Results'!$G$4:$G$75,$C13,'Match Results'!$H$4:$H$75,"Final") | J13: =G13-H13 | K13: =D13*3+E13 | L13: =1+SUMPRODUCT(($A$4:$A$51=$A13)*(($K$4:$K$51>K13)+(($K$4:$K$51=K13)*($J$4:$J$51>J13))+(($K$4:$K$51=K13)*($J$4:$J$51=J13)*($G$4:$G$51>G13))+(($K$4:$K$51=K13)*($J$4:$J$51=J13)*($G$4:$G$51=G13)*($B$4:$B$51<B13)))) | M13: =IF(L13=3,1+SUMPRODUCT(($L$4:$L$51=3)*(($K$4:$K$51>K13)+(($K$4:$K$51=K13)*($J$4:$J$51>J13))+(($K$4:$K$51=K13)*($J$4:$J$51=J13)*($G$4:$G$51>G13))+(($K$4:$K$51=K13)*($J$4:$J$51=J13)*($G$4:$G$51=G13)*(ROW($A$4:$A$51)<ROW(A13))))),"") | N13: =IF(COUNTIFS('Match Results'!$C$4:$C$75,$A13,'Match Results'!$H$4:$H$75,"Final")<6,IF(I13=0,"Pending","In play"),IF(L13<=2,"Qualified",IF(AND(L13=3,M13<=8),"Qualified best 3rd","Eliminated"))) | O13: =C13
A14: C | B14: 3 | C14: Scotland | D14: =COUNTIFS('Match Results'!$C$4:$C$75,$A14,'Match Results'!$I$4:$I$75,$C14) | E14: =COUNTIFS('Match Results'!$C$4:$C$75,$A14,'Match Results'!$D$4:$D$75,$C14,'Match Results'!$I$4:$I$75,"Draw")+COUNTIFS('Match Results'!$C$4:$C$75,$A14,'Match Results'!$G$4:$G$75,$C14,'Match Results'!$I$4:$I$75,"Draw") | F14: =I14-D14-E14 | G14: =SUMIFS('Match Results'!$E$4:$E$75,'Match Results'!$C$4:$C$75,$A14,'Match Results'!$D$4:$D$75,$C14)+SUMIFS('Match Results'!$F$4:$F$75,'Match Results'!$C$4:$C$75,$A14,'Match Results'!$G$4:$G$75,$C14) | H14: =SUMIFS('Match Results'!$F$4:$F$75,'Match Results'!$C$4:$C$75,$A14,'Match Results'!$D$4:$D$75,$C14)+SUMIFS('Match Results'!$E$4:$E$75,'Match Results'!$C$4:$C$75,$A14,'Match Results'!$G$4:$G$75,$C14) | I14: =COUNTIFS('Match Results'!$C$4:$C$75,$A14,'Match Results'!$D$4:$D$75,$C14,'Match Results'!$H$4:$H$75,"Final")+COUNTIFS('Match Results'!$C$4:$C$75,$A14,'Match Results'!$G$4:$G$75,$C14,'Match Results'!$H$4:$H$75,"Final") | J14: =G14-H14 | K14: =D14*3+E14 | L14: =1+SUMPRODUCT(($A$4:$A$51=$A14)*(($K$4:$K$51>K14)+(($K$4:$K$51=K14)*($J$4:$J$51>J14))+(($K$4:$K$51=K14)*($J$4:$J$51=J14)*($G$4:$G$51>G14))+(($K$4:$K$51=K14)*($J$4:$J$51=J14)*($G$4:$G$51=G14)*($B$4:$B$51<B14)))) | M14: =IF(L14=3,1+SUMPRODUCT(($L$4:$L$51=3)*(($K$4:$K$51>K14)+(($K$4:$K$51=K14)*($J$4:$J$51>J14))+(($K$4:$K$51=K14)*($J$4:$J$51=J14)*($G$4:$G$51>G14))+(($K$4:$K$51=K14)*($J$4:$J$51=J14)*($G$4:$G$51=G14)*(ROW($A$4:$A$51)<ROW(A14))))),"") | N14: =IF(COUNTIFS('Match Results'!$C$4:$C$75,$A14,'Match Results'!$H$4:$H$75,"Final")<6,IF(I14=0,"Pending","In play"),IF(L14<=2,"Qualified",IF(AND(L14=3,M14<=8),"Qualified best 3rd","Eliminated"))) | O14: =C14
A15: C | B15: 4 | C15: Haiti | D15: =COUNTIFS('Match Results'!$C$4:$C$75,$A15,'Match Results'!$I$4:$I$75,$C15) | E15: =COUNTIFS('Match Results'!$C$4:$C$75,$A15,'Match Results'!$D$4:$D$75,$C15,'Match Results'!$I$4:$I$75,"Draw")+COUNTIFS('Match Results'!$C$4:$C$75,$A15,'Match Results'!$G$4:$G$75,$C15,'Match Results'!$I$4:$I$75,"Draw") | F15: =I15-D15-E15 | G15: =SUMIFS('Match Results'!$E$4:$E$75,'Match Results'!$C$4:$C$75,$A15,'Match Results'!$D$4:$D$75,$C15)+SUMIFS('Match Results'!$F$4:$F$75,'Match Results'!$C$4:$C$75,$A15,'Match Results'!$G$4:$G$75,$C15) | H15: =SUMIFS('Match Results'!$F$4:$F$75,'Match Results'!$C$4:$C$75,$A15,'Match Results'!$D$4:$D$75,$C15)+SUMIFS('Match Results'!$E$4:$E$75,'Match Results'!$C$4:$C$75,$A15,'Match Results'!$G$4:$G$75,$C15) | I15: =COUNTIFS('Match Results'!$C$4:$C$75,$A15,'Match Results'!$D$4:$D$75,$C15,'Match Results'!$H$4:$H$75,"Final")+COUNTIFS('Match Results'!$C$4:$C$75,$A15,'Match Results'!$G$4:$G$75,$C15,'Match Results'!$H$4:$H$75,"Final") | J15: =G15-H15 | K15: =D15*3+E15 | L15: =1+SUMPRODUCT(($A$4:$A$51=$A15)*(($K$4:$K$51>K15)+(($K$4:$K$51=K15)*($J$4:$J$51>J15))+(($K$4:$K$51=K15)*($J$4:$J$51=J15)*($G$4:$G$51>G15))+(($K$4:$K$51=K15)*($J$4:$J$51=J15)*($G$4:$G$51=G15)*($B$4:$B$51<B15)))) | M15: =IF(L15=3,1+SUMPRODUCT(($L$4:$L$51=3)*(($K$4:$K$51>K15)+(($K$4:$K$51=K15)*($J$4:$J$51>J15))+(($K$4:$K$51=K15)*($J$4:$J$51=J15)*($G$4:$G$51>G15))+(($K$4:$K$51=K15)*($J$4:$J$51=J15)*($G$4:$G$51=G15)*(ROW($A$4:$A$51)<ROW(A15))))),"") | N15: =IF(COUNTIFS('Match Results'!$C$4:$C$75,$A15,'Match Results'!$H$4:$H$75,"Final")<6,IF(I15=0,"Pending","In play"),IF(L15<=2,"Qualified",IF(AND(L15=3,M15<=8),"Qualified best 3rd","Eliminated"))) | O15: =C15
... A51: L | B51: 4 | C51: Panama | D51: =COUNTIFS('Match Results'!$C$4:$C$75,$A51,'Match Results'!$I$4:$I$75,$C51) | E51: =COUNTIFS('Match Results'!$C$4:$C$75,$A51,'Match Results'!$D$4:$D$75,$C51,'Match Results'!$I$4:$I$75,"Draw")+COUNTIFS('Match Results'!$C$4:$C$75,$A51,'Match Results'!$G$4:$G$75,$C51,'Match Results'!$I$4:$I$75,"Draw") | F51: =I51-D51-E51 | G51: =SUMIFS('Match Results'!$E$4:$E$75,'Match Results'!$C$4:$C$75,$A51,'Match Results'!$D$4:$D$75,$C51)+SUMIFS('Match Results'!$F$4:$F$75,'Match Results'!$C$4:$C$75,$A51,'Match Results'!$G$4:$G$75,$C51) | H51: =SUMIFS('Match Results'!$F$4:$F$75,'Match Results'!$C$4:$C$75,$A51,'Match Results'!$D$4:$D$75,$C51)+SUMIFS('Match Results'!$E$4:$E$75,'Match Results'!$C$4:$C$75,$A51,'Match Results'!$G$4:$G$75,$C51) | I51: =COUNTIFS('Match Results'!$C$4:$C$75,$A51,'Match Results'!$D$4:$D$75,$C51,'Match Results'!$H$4:$H$75,"Final")+COUNTIFS('Match Results'!$C$4:$C$75,$A51,'Match Results'!$G$4:$G$75,$C51,'Match Results'!$H$4:$H$75,"Final") | J51: =G51-H51 | K51: =D51*3+E51 | L51: =1+SUMPRODUCT(($A$4:$A$51=$A51)*(($K$4:$K$51>K51)+(($K$4:$K$51=K51)*($J$4:$J$51>J51))+(($K$4:$K$51=K51)*($J$4:$J$51=J51)*($G$4:$G$51>G51))+(($K$4:$K$51=K51)*($J$4:$J$51=J51)*($G$4:$G$51=G51)*($B$4:$B$51<B51)))) | M51: =IF(L51=3,1+SUMPRODUCT(($L$4:$L$51=3)*(($K$4:$K$51>K51)+(($K$4:$K$51=K51)*($J$4:$J$51>J51))+(($K$4:$K$51=K51)*($J$4:$J$51=J51)*($G$4:$G$51>G51))+(($K$4:$K$51=K51)*($J$4:$J$51=J51)*($G$4:$G$51=G51)*(ROW($A$4:$A$51)<ROW(A51))))),"") | N51: =IF(COUNTIFS('Match Results'!$C$4:$C$75,$A51,'Match Results'!$H$4:$H$75,"Final")<6,IF(I51=0,"Pending","In play"),IF(L51<=2,"Qualified",IF(AND(L51=3,M51<=8),"Qualified best 3rd","Eliminated"))) | O51: =C51

Sheet Setup
A1: Setup - official teams, R32 seeding and Annex C third-place logic
A2: All Teams | B2: Flag Image | C2: Official Match | D2: Team 1 | E2: Team 2 | G2: Winner Dropdown Helper | H2: Option | I2: Internal Match | K2: Winner Output Helper | L2: Winner | O2: Projected eight best third-place groups and Annex C assignments
A3: Mexico | C3: M74 | D3: =IFERROR(INDEX('Group Stage'!$C$4:$C$51,SUMPRODUCT(('Group Stage'!$A$4:$A$51="E")*('Group Stage'!$L$4:$L$51=1)*(ROW('Group Stage'!$C$4:$C$51)-ROW('Group Stage'!$C$4)+1))),"E1 TBD") | E3: =IFERROR(INDEX('Group Stage'!$C$4:$C$51,SUMPRODUCT(('Group Stage'!$A$4:$A$51=RIGHT($R$6,1))*('Group Stage'!$L$4:$L$51=3)*(ROW('Group Stage'!$C$4:$C$51)-ROW('Group Stage'!$C$4)+1))),"3P A/B/C/D/F TBD") | G3: R32-01 | H3: ='Tournament Map'!A7 | I3: R32-01 | K3: R32-01 | L3: ='Tournament Map'!B9 | O3: =IF(COUNTIFS('Group Stage'!$A$4:$A$51,"A",'Group Stage'!$L$4:$L$51,3,'Group Stage'!$M$4:$M$51,"<=8")>0,"A","")&IF(COUNTIFS('Group Stage'!$A$4:$A$51,"B",'Group Stage'!$L$4:$L$51,3,'Group Stage'!$M$4:$M$51,"<=8")>0,"B","")&IF(COUNTIFS('Group Stage'!$A$4:$A$51,"C",'Group Stage'!$L$4:$L$51,3,'Group Stage'!$M$4:$M$51,"<=8")>0,"C","")&IF(COUNTIFS('Group Stage'!$A$4:$A$51,"D",'Group Stage'!$L$4:$L$51,3,'Group Stage'!$M$4:$M$51,"<=8")>0,"D","")&IF(COUNTIFS('Group Stage'!$A$4:$A$51,"E",'Group Stage'!$L$4:$L$51,3,'Group Stage'!$M$4:$M$51,"<=8")>0,"E","")&IF(COUNTIFS('Group Stage'!$A$4:$A$51,"F",'Group Stage'!$L$4:$L$51,3,'Group Stage'!$M$4:$M$51,"<=8")>0,"F","")&IF(COUNTIFS('Group Stage'!$A$4:$A$51,"G",'Group Stage'!$L$4:$L$51,3,'Group Stage'!$M$4:$M$51,"<=8")>0,"G","")&IF(COUNTIFS('Group Stage'!$A$4:$A$51,"H",'Group Stage'!$L$4:$L$51,3,'Group Stage'!$M$4:$M$51,"<=8")>0,"H","")&IF(COUNTIFS('Group Stage'!$A$4:$A$51,"I",'Group Stage'!$L$4:$L$51,3,'Group Stage'!$M$4:$M$51,"<=8")>0,"I","")&IF(COUNTIFS('Group Stage'!$A$4:$A$51,"J",'Group Stage'!$L$4:$L$51,3,'Group Stage'!$M$4:$M$51,"<=8")>0,"J","")&IF(COUNTIFS('Group Stage'!$A$4:$A$51,"K",'Group Stage'!$L$4:$L$51,3,'Group Stage'!$M$4:$M$51,"<=8")>0,"K","")&IF(COUNTIFS('Group Stage'!$A$4:$A$51,"L",'Group Stage'!$L$4:$L$51,3,'Group Stage'!$M$4:$M$51,"<=8")>0,"L","")
A4: South Africa | C4: M77 | D4: =IFERROR(INDEX('Group Stage'!$C$4:$C$51,SUMPRODUCT(('Group Stage'!$A$4:$A$51="I")*('Group Stage'!$L$4:$L$51=1)*(ROW('Group Stage'!$C$4:$C$51)-ROW('Group Stage'!$C$4)+1))),"I1 TBD") | E4: =IFERROR(INDEX('Group Stage'!$C$4:$C$51,SUMPRODUCT(('Group Stage'!$A$4:$A$51=RIGHT($T$6,1))*('Group Stage'!$L$4:$L$51=3)*(ROW('Group Stage'!$C$4:$C$51)-ROW('Group Stage'!$C$4)+1))),"3P C/D/F/G/H TBD") | H4: ='Tournament Map'!A8 | I4: R32-01 | K4: R32-02 | L4: ='Tournament Map'!B15 | O4: 1A | P4: 1B | Q4: 1D | R4: 1E | S4: 1G | T4: 1I | U4: 1K | V4: 1L
A5: Korea Republic | C5: M73 | D5: =IFERROR(INDEX('Group Stage'!$C$4:$C$51,SUMPRODUCT(('Group Stage'!$A$4:$A$51="A")*('Group Stage'!$L$4:$L$51=2)*(ROW('Group Stage'!$C$4:$C$51)-ROW('Group Stage'!$C$4)+1))),"A2 TBD") | E5: =IFERROR(INDEX('Group Stage'!$C$4:$C$51,SUMPRODUCT(('Group Stage'!$A$4:$A$51="B")*('Group Stage'!$L$4:$L$51=2)*(ROW('Group Stage'!$C$4:$C$51)-ROW('Group Stage'!$C$4)+1))),"B2 TBD") | G5: R32-02 | H5: ='Tournament Map'!A13 | I5: R32-02 | K5: R32-03 | L5: ='Tournament Map'!B21 | O5: Assigned 3rd | P5: Assigned 3rd | Q5: Assigned 3rd | R5: Assigned 3rd | S5: Assigned 3rd | T5: Assigned 3rd | U5: Assigned 3rd | V5: Assigned 3rd
A6: Czechia | C6: M75 | D6: =IFERROR(INDEX('Group Stage'!$C$4:$C$51,SUMPRODUCT(('Group Stage'!$A$4:$A$51="F")*('Group Stage'!$L$4:$L$51=1)*(ROW('Group Stage'!$C$4:$C$51)-ROW('Group Stage'!$C$4)+1))),"F1 TBD") | E6: =IFERROR(INDEX('Group Stage'!$C$4:$C$51,SUMPRODUCT(('Group Stage'!$A$4:$A$51="C")*('Group Stage'!$L$4:$L$51=2)*(ROW('Group Stage'!$C$4:$C$51)-ROW('Group Stage'!$C$4)+1))),"C2 TBD") | H6: ='Tournament Map'!A14 | I6: R32-02 | K6: R32-04 | L6: ='Tournament Map'!B27 | O6: =IFERROR(INDEX('Annex C'!$B$2:$I$496,MATCH($O$3,'Annex C'!$J$2:$J$496,0),MATCH(O$4,'Annex C'!$B$1:$I$1,0)),"") | P6: =IFERROR(INDEX('Annex C'!$B$2:$I$496,MATCH($O$3,'Annex C'!$J$2:$J$496,0),MATCH(P$4,'Annex C'!$B$1:$I$1,0)),"") | Q6: =IFERROR(INDEX('Annex C'!$B$2:$I$496,MATCH($O$3,'Annex C'!$J$2:$J$496,0),MATCH(Q$4,'Annex C'!$B$1:$I$1,0)),"") | R6: =IFERROR(INDEX('Annex C'!$B$2:$I$496,MATCH($O$3,'Annex C'!$J$2:$J$496,0),MATCH(R$4,'Annex C'!$B$1:$I$1,0)),"") | S6: =IFERROR(INDEX('Annex C'!$B$2:$I$496,MATCH($O$3,'Annex C'!$J$2:$J$496,0),MATCH(S$4,'Annex C'!$B$1:$I$1,0)),"") | T6: =IFERROR(INDEX('Annex C'!$B$2:$I$496,MATCH($O$3,'Annex C'!$J$2:$J$496,0),MATCH(T$4,'Annex C'!$B$1:$I$1,0)),"") | U6: =IFERROR(INDEX('Annex C'!$B$2:$I$496,MATCH($O$3,'Annex C'!$J$2:$J$496,0),MATCH(U$4,'Annex C'!$B$1:$I$1,0)),"") | V6: =IFERROR(INDEX('Annex C'!$B$2:$I$496,MATCH($O$3,'Annex C'!$J$2:$J$496,0),MATCH(V$4,'Annex C'!$B$1:$I$1,0)),"")
A7: Canada | C7: M83 | D7: =IFERROR(INDEX('Group Stage'!$C$4:$C$51,SUMPRODUCT(('Group Stage'!$A$4:$A$51="K")*('Group Stage'!$L$4:$L$51=2)*(ROW('Group Stage'!$C$4:$C$51)-ROW('Group Stage'!$C$4)+1))),"K2 TBD") | E7: =IFERROR(INDEX('Group Stage'!$C$4:$C$51,SUMPRODUCT(('Group Stage'!$A$4:$A$51="L")*('Group Stage'!$L$4:$L$51=2)*(ROW('Group Stage'!$C$4:$C$51)-ROW('Group Stage'!$C$4)+1))),"L2 TBD") | G7: R32-03 | H7: ='Tournament Map'!A19 | I7: R32-03 | K7: R32-05 | L7: ='Tournament Map'!B33
A8: Bosnia and Herzegovina | C8: M84 | D8: =IFERROR(INDEX('Group Stage'!$C$4:$C$51,SUMPRODUCT(('Group Stage'!$A$4:$A$51="H")*('Group Stage'!$L$4:$L$51=1)*(ROW('Group Stage'!$C$4:$C$51)-ROW('Group Stage'!$C$4)+1))),"H1 TBD") | E8: =IFERROR(INDEX('Group Stage'!$C$4:$C$51,SUMPRODUCT(('Group Stage'!$A$4:$A$51="J")*('Group Stage'!$L$4:$L$51=2)*(ROW('Group Stage'!$C$4:$C$51)-ROW('Group Stage'!$C$4)+1))),"J2 TBD") | H8: ='Tournament Map'!A20 | I8: R32-03 | K8: R32-06 | L8: ='Tournament Map'!B39
A9: Switzerland | C9: M81 | D9: =IFERROR(INDEX('Group Stage'!$C$4:$C$51,SUMPRODUCT(('Group Stage'!$A$4:$A$51="D")*('Group Stage'!$L$4:$L$51=1)*(ROW('Group Stage'!$C$4:$C$51)-ROW('Group Stage'!$C$4)+1))),"D1 TBD") | E9: =IFERROR(INDEX('Group Stage'!$C$4:$C$51,SUMPRODUCT(('Group Stage'!$A$4:$A$51=RIGHT($Q$6,1))*('Group Stage'!$L$4:$L$51=3)*(ROW('Group Stage'!$C$4:$C$51)-ROW('Group Stage'!$C$4)+1))),"3P B/E/F/I/J TBD") | G9: R32-04 | H9: ='Tournament Map'!A25 | I9: R32-04 | K9: R32-07 | L9: ='Tournament Map'!B45
A10: Qatar | C10: M82 | D10: =IFERROR(INDEX('Group Stage'!$C$4:$C$51,SUMPRODUCT(('Group Stage'!$A$4:$A$51="G")*('Group Stage'!$L$4:$L$51=1)*(ROW('Group Stage'!$C$4:$C$51)-ROW('Group Stage'!$C$4)+1))),"G1 TBD") | E10: =IFERROR(INDEX('Group Stage'!$C$4:$C$51,SUMPRODUCT(('Group Stage'!$A$4:$A$51=RIGHT($S$6,1))*('Group Stage'!$L$4:$L$51=3)*(ROW('Group Stage'!$C$4:$C$51)-ROW('Group Stage'!$C$4)+1))),"3P A/E/H/I/J TBD") | H10: ='Tournament Map'!A26 | I10: R32-04 | K10: R32-08 | L10: ='Tournament Map'!B51
A11: Brazil | C11: M76 | D11: =IFERROR(INDEX('Group Stage'!$C$4:$C$51,SUMPRODUCT(('Group Stage'!$A$4:$A$51="C")*('Group Stage'!$L$4:$L$51=1)*(ROW('Group Stage'!$C$4:$C$51)-ROW('Group Stage'!$C$4)+1))),"C1 TBD") | E11: =IFERROR(INDEX('Group Stage'!$C$4:$C$51,SUMPRODUCT(('Group Stage'!$A$4:$A$51="F")*('Group Stage'!$L$4:$L$51=2)*(ROW('Group Stage'!$C$4:$C$51)-ROW('Group Stage'!$C$4)+1))),"F2 TBD") | G11: R32-05 | H11: ='Tournament Map'!A31 | I11: R32-05 | K11: R32-09 | L11: ='Tournament Map'!AP9
A12: Morocco | C12: M78 | D12: =IFERROR(INDEX('Group Stage'!$C$4:$C$51,SUMPRODUCT(('Group Stage'!$A$4:$A$51="E")*('Group Stage'!$L$4:$L$51=2)*(ROW('Group Stage'!$C$4:$C$51)-ROW('Group Stage'!$C$4)+1))),"E2 TBD") | E12: =IFERROR(INDEX('Group Stage'!$C$4:$C$51,SUMPRODUCT(('Group Stage'!$A$4:$A$51="I")*('Group Stage'!$L$4:$L$51=2)*(ROW('Group Stage'!$C$4:$C$51)-ROW('Group Stage'!$C$4)+1))),"I2 TBD") | H12: ='Tournament Map'!A32 | I12: R32-05 | K12: R32-10 | L12: ='Tournament Map'!AP15
A13: Scotland | C13: M79 | D13: =IFERROR(INDEX('Group Stage'!$C$4:$C$51,SUMPRODUCT(('Group Stage'!$A$4:$A$51="A")*('Group Stage'!$L$4:$L$51=1)*(ROW('Group Stage'!$C$4:$C$51)-ROW('Group Stage'!$C$4)+1))),"A1 TBD") | E13: =IFERROR(INDEX('Group Stage'!$C$4:$C$51,SUMPRODUCT(('Group Stage'!$A$4:$A$51=RIGHT($O$6,1))*('Group Stage'!$L$4:$L$51=3)*(ROW('Group Stage'!$C$4:$C$51)-ROW('Group Stage'!$C$4)+1))),"3P C/E/F/H/I TBD") | G13: R32-06 | H13: ='Tournament Map'!A37 | I13: R32-06 | K13: R32-11 | L13: ='Tournament Map'!AP21
A14: Haiti | C14: M80 | D14: =IFERROR(INDEX('Group Stage'!$C$4:$C$51,SUMPRODUCT(('Group Stage'!$A$4:$A$51="L")*('Group Stage'!$L$4:$L$51=1)*(ROW('Group Stage'!$C$4:$C$51)-ROW('Group Stage'!$C$4)+1))),"L1 TBD") | E14: =IFERROR(INDEX('Group Stage'!$C$4:$C$51,SUMPRODUCT(('Group Stage'!$A$4:$A$51=RIGHT($V$6,1))*('Group Stage'!$L$4:$L$51=3)*(ROW('Group Stage'!$C$4:$C$51)-ROW('Group Stage'!$C$4)+1))),"3P E/H/I/J/K TBD") | H14: ='Tournament Map'!A38 | I14: R32-06 | K14: R32-12 | L14: ='Tournament Map'!AP27
A15: USA | C15: M86 | D15: =IFERROR(INDEX('Group Stage'!$C$4:$C$51,SUMPRODUCT(('Group Stage'!$A$4:$A$51="J")*('Group Stage'!$L$4:$L$51=1)*(ROW('Group Stage'!$C$4:$C$51)-ROW('Group Stage'!$C$4)+1))),"J1 TBD") | E15: =IFERROR(INDEX('Group Stage'!$C$4:$C$51,SUMPRODUCT(('Group Stage'!$A$4:$A$51="H")*('Group Stage'!$L$4:$L$51=2)*(ROW('Group Stage'!$C$4:$C$51)-ROW('Group Stage'!$C$4)+1))),"H2 TBD") | G15: R32-07 | H15: ='Tournament Map'!A43 | I15: R32-07 | K15: R32-13 | L15: ='Tournament Map'!AP33
A16: Paraguay | C16: M88 | D16: =IFERROR(INDEX('Group Stage'!$C$4:$C$51,SUMPRODUCT(('Group Stage'!$A$4:$A$51="D")*('Group Stage'!$L$4:$L$51=2)*(ROW('Group Stage'!$C$4:$C$51)-ROW('Group Stage'!$C$4)+1))),"D2 TBD") | E16: =IFERROR(INDEX('Group Stage'!$C$4:$C$51,SUMPRODUCT(('Group Stage'!$A$4:$A$51="G")*('Group Stage'!$L$4:$L$51=2)*(ROW('Group Stage'!$C$4:$C$51)-ROW('Group Stage'!$C$4)+1))),"G2 TBD") | H16: ='Tournament Map'!A44 | I16: R32-07 | K16: R32-14 | L16: ='Tournament Map'!AP39
A17: Australia | C17: M85 | D17: =IFERROR(INDEX('Group Stage'!$C$4:$C$51,SUMPRODUCT(('Group Stage'!$A$4:$A$51="B")*('Group Stage'!$L$4:$L$51=1)*(ROW('Group Stage'!$C$4:$C$51)-ROW('Group Stage'!$C$4)+1))),"B1 TBD") | E17: =IFERROR(INDEX('Group Stage'!$C$4:$C$51,SUMPRODUCT(('Group Stage'!$A$4:$A$51=RIGHT($P$6,1))*('Group Stage'!$L$4:$L$51=3)*(ROW('Group Stage'!$C$4:$C$51)-ROW('Group Stage'!$C$4)+1))),"3P E/F/G/I/J TBD") | G17: R32-08 | H17: ='Tournament Map'!A49 | I17: R32-08 | K17: R32-15 | L17: ='Tournament Map'!AP45
A18: Türkiye | C18: M87 | D18: =IFERROR(INDEX('Group Stage'!$C$4:$C$51,SUMPRODUCT(('Group Stage'!$A$4:$A$51="K")*('Group Stage'!$L$4:$L$51=1)*(ROW('Group Stage'!$C$4:$C$51)-ROW('Group Stage'!$C$4)+1))),"K1 TBD") | E18: =IFERROR(INDEX('Group Stage'!$C$4:$C$51,SUMPRODUCT(('Group Stage'!$A$4:$A$51=RIGHT($U$6,1))*('Group Stage'!$L$4:$L$51=3)*(ROW('Group Stage'!$C$4:$C$51)-ROW('Group Stage'!$C$4)+1))),"3P D/E/I/J/L TBD") | H18: ='Tournament Map'!A50 | I18: R32-08 | K18: R32-16 | L18: ='Tournament Map'!AP51
A19: Germany | G19: R32-09 | H19: ='Tournament Map'!AO7 | I19: R32-09 | K19: R16-L1 | L19: ='Tournament Map'!G12
A20: Curaçao | H20: ='Tournament Map'!AO8 | I20: R32-09 | K20: R16-L2 | L20: ='Tournament Map'!G24
A21: Côte d'Ivoire | G21: R32-10 | H21: ='Tournament Map'!AO13 | I21: R32-10 | K21: R16-L3 | L21: ='Tournament Map'!G36
A22: Ecuador | H22: ='Tournament Map'!AO14 | I22: R32-10 | K22: R16-L4 | L22: ='Tournament Map'!G48
A23: Netherlands | G23: R32-11 | H23: ='Tournament Map'!AO19 | I23: R32-11 | K23: R16-R1 | L23: ='Tournament Map'!AK12
A24: Japan | H24: ='Tournament Map'!AO20 | I24: R32-11 | K24: R16-R2 | L24: ='Tournament Map'!AK24
A25: Sweden | G25: R32-12 | H25: ='Tournament Map'!AO25 | I25: R32-12 | K25: R16-R3 | L25: ='Tournament Map'!AK36
A26: Tunisia | H26: ='Tournament Map'!AO26 | I26: R32-12 | K26: R16-R4 | L26: ='Tournament Map'!AK48
A27: Belgium | G27: R32-13 | H27: ='Tournament Map'!AO31 | I27: R32-13 | K27: QF-L1 | L27: ='Tournament Map'!L18
A28: Egypt | H28: ='Tournament Map'!AO32 | I28: R32-13 | K28: QF-L2 | L28: ='Tournament Map'!L42
A29: IR Iran | G29: R32-14 | H29: ='Tournament Map'!AO37 | I29: R32-14 | K29: QF-R1 | L29: ='Tournament Map'!AF18
A30: New Zealand | H30: ='Tournament Map'!AO38 | I30: R32-14 | K30: QF-R2 | L30: ='Tournament Map'!AF42
A31: Spain | G31: R32-15 | H31: ='Tournament Map'!AO43 | I31: R32-15 | K31: SF-L | L31: ='Tournament Map'!Q30
A32: Cabo Verde | H32: ='Tournament Map'!AO44 | I32: R32-15 | K32: SF-R | L32: ='Tournament Map'!AA30
A33: Saudi Arabia | G33: R32-16 | H33: ='Tournament Map'!AO49 | I33: R32-16 | K33: FINAL | L33: ='Tournament Map'!V30
A34: Uruguay | H34: ='Tournament Map'!AO50 | I34: R32-16 | K34: THIRD | L34: ='Tournament Map'!V41
A35: France | G35: R16-L1 | H35: ='Tournament Map'!F10 | I35: R16-L1
A36: Senegal | H36: ='Tournament Map'!F11 | I36: R16-L1
A37: Iraq | G37: R16-L2 | H37: ='Tournament Map'!F22 | I37: R16-L2
A38: Norway | H38: ='Tournament Map'!F23 | I38: R16-L2
A39: Argentina | G39: R16-L3 | H39: ='Tournament Map'!F34 | I39: R16-L3
A40: Algeria | H40: ='Tournament Map'!F35 | I40: R16-L3
...

Sheet Tournament Map
A1: FIFA 2026 Tournament Progress Map
A2: Teams and results are driven from Match Results. Yellow score/pick cells still let you override winners manually.
A4: Round of 32 | F4: Round of 16 | K4: Quarterfinals | U4: CHAMPION | AE4: Quarterfinals | AJ4: Round of 16 | AO4: Round of 32
U5: =IF(V30<>"",V30,"TBD")
A6: M74 | Round of 32 | AO6: M76 | Round of 32
A7: =Setup!$D$3 | C7: =IF('Knockout Pitch Map'!D6="","",'Knockout Pitch Map'!D6) | D7: Pick | AO7: =Setup!$D$11 | AQ7: =IF('Knockout Pitch Map'!AR6="","",'Knockout Pitch Map'!AR6) | AR7: Pick
A8: =Setup!$E$3 | C8: =IF('Knockout Pitch Map'!D7="","",'Knockout Pitch Map'!D7) | D8: =IF('Knockout Pitch Map'!B8="","",'Knockout Pitch Map'!B8) | U8: PROGRESS | AO8: =Setup!$E$11 | AQ8: =IF('Knockout Pitch Map'!AR7="","",'Knockout Pitch Map'!AR7) | AR8: =IF('Knockout Pitch Map'!AP8="","",'Knockout Pitch Map'!AP8)
A9: Winner | B9: =IF(D8<>"",D8,IF(AND(ISNUMBER(C7),ISNUMBER(C8),C7<>C8),IF(C7>C8,A7,A8),"")) | F9: M89 | Round of 16 | U9: Matches decided | W9: =SUM(--(LEN(B9)>0),--(LEN(B15)>0),--(LEN(B21)>0),--(LEN(B27)>0),--(LEN(B33)>0),--(LEN(B39)>0),--(LEN(B45)>0),--(LEN(B51)>0),--(LEN(AP9)>0),--(LEN(AP15)>0),--(LEN(AP21)>0),--(LEN(AP27)>0),--(LEN(AP33)>0),--(LEN(AP39)>0),--(LEN(AP45)>0),--(LEN(AP51)>0),--(LEN(G12)>0),--(LEN(G24)>0),--(LEN(G36)>0),--(LEN(G48)>0),--(LEN(AK12)>0),--(LEN(AK24)>0),--(LEN(AK36)>0),--(LEN(AK48)>0),--(LEN(L18)>0),--(LEN(L42)>0),--(LEN(AF18)>0),--(LEN(AF42)>0),--(LEN(Q30)>0),--(LEN(AA30)>0),--(LEN(V30)>0),--(LEN(V41)>0))&" / 32" | AJ9: M91 | Round of 16 | AO9: Winner | AP9: =IF(AR8<>"",AR8,IF(AND(ISNUMBER(AQ7),ISNUMBER(AQ8),AQ7<>AQ8),IF(AQ7>AQ8,AO7,AO8),""))
F10: =IF(OR(B9="",B9=0),"",B9) | H10: =IF('Knockout Pitch Map'!I9="","",'Knockout Pitch Map'!I9) | I10: Pick | U10: Completion | W10: =SUM(--(LEN(B9)>0),--(LEN(B15)>0),--(LEN(B21)>0),--(LEN(B27)>0),--(LEN(B33)>0),--(LEN(B39)>0),--(LEN(B45)>0),--(LEN(B51)>0),--(LEN(AP9)>0),--(LEN(AP15)>0),--(LEN(AP21)>0),--(LEN(AP27)>0),--(LEN(AP33)>0),--(LEN(AP39)>0),--(LEN(AP45)>0),--(LEN(AP51)>0),--(LEN(G12)>0),--(LEN(G24)>0),--(LEN(G36)>0),--(LEN(G48)>0),--(LEN(AK12)>0),--(LEN(AK24)>0),--(LEN(AK36)>0),--(LEN(AK48)>0),--(LEN(L18)>0),--(LEN(L42)>0),--(LEN(AF18)>0),--(LEN(AF42)>0),--(LEN(Q30)>0),--(LEN(AA30)>0),--(LEN(V30)>0),--(LEN(V41)>0))/32 | AJ10: =IF(OR(AP9="",AP9=0),"",AP9) | AL10: =IF('Knockout Pitch Map'!AM9="","",'Knockout Pitch Map'!AM9) | AM10: Pick
F11: =IF(OR(B15="",B15=0),"",B15) | H11: =IF('Knockout Pitch Map'!I10="","",'Knockout Pitch Map'!I10) | I11: =IF('Knockout Pitch Map'!G11="","",'Knockout Pitch Map'!G11) | AJ11: =IF(OR(AP15="",AP15=0),"",AP15) | AL11: =IF('Knockout Pitch Map'!AM10="","",'Knockout Pitch Map'!AM10) | AM11: =IF('Knockout Pitch Map'!AK11="","",'Knockout Pitch Map'!AK11)
A12: M77 | Round of 32 | F12: Winner | G12: =IF(I11<>"",I11,IF(AND(ISNUMBER(H10),ISNUMBER(H11),H10<>H11),IF(H10>H11,F10,F11),"")) | AJ12: Winner | AK12: =IF(AM11<>"",AM11,IF(AND(ISNUMBER(AL10),ISNUMBER(AL11),AL10<>AL11),IF(AL10>AL11,AJ10,AJ11),"")) | AO12: M78 | Round of 32
A13: =Setup!$D$4 | C13: =IF('Knockout Pitch Map'!D13="","",'Knockout Pitch Map'!D13) | D13: Pick | U13: FINAL RESULT | AO13: =Setup!$D$12 | AQ13: =IF('Knockout Pitch Map'!AR13="","",'Knockout Pitch Map'!AR13) | AR13: Pick
A14: =Setup!$E$4 | C14: =IF('Knockout Pitch Map'!D14="","",'Knockout Pitch Map'!D14) | D14: =IF('Knockout Pitch Map'!B15="","",'Knockout Pitch Map'!B15) | U14: Winner | W14: =IF(V30<>"",V30,"") | AO14: =Setup!$E$12 | AQ14: =IF('Knockout Pitch Map'!AR14="","",'Knockout Pitch Map'!AR14) | AR14: =IF('Knockout Pitch Map'!AP15="","",'Knockout Pitch Map'!AP15)
A15: Winner | B15: =IF(D14<>"",D14,IF(AND(ISNUMBER(C13),ISNUMBER(C14),C13<>C14),IF(C13>C14,A13,A14),"")) | K15: M97 | Quarterfinal | U15: Runner Up | W15: =IF(V30<>"",IF(V30=U28,U29,U28),"") | AE15: M99 | Quarterfinal | AO15: Winner | AP15: =IF(AR14<>"",AR14,IF(AND(ISNUMBER(AQ13),ISNUMBER(AQ14),AQ13<>AQ14),IF(AQ13>AQ14,AO13,AO14),""))
K16: =IF(OR(G12="",G12=0),"",G12) | M16: =IF('Knockout Pitch Map'!N16="","",'Knockout Pitch Map'!N16) | N16: Pick | U16: Third Place | W16: =IF(V41<>"",V41,"") | AE16: =IF(OR(AK12="",AK12=0),"",AK12) | AG16: =IF('Knockout Pitch Map'!AH16="","",'Knockout Pitch Map'!AH16) | AH16: Pick
K17: =IF(OR(G24="",G24=0),"",G24) | M17: =IF('Knockout Pitch Map'!N17="","",'Knockout Pitch Map'!N17) | N17: =IF('Knockout Pitch Map'!L18="","",'Knockout Pitch Map'!L18) | AE17: =IF(OR(AK24="",AK24=0),"",AK24) | AG17: =IF('Knockout Pitch Map'!AH17="","",'Knockout Pitch Map'!AH17) | AH17: =IF('Knockout Pitch Map'!AF18="","",'Knockout Pitch Map'!AF18)
A18: M73 | Round of 32 | K18: Winner | L18: =IF(N17<>"",N17,IF(AND(ISNUMBER(M16),ISNUMBER(M17),M16<>M17),IF(M16>M17,K16,K17),"")) | AE18: Winner | AF18: =IF(AH17<>"",AH17,IF(AND(ISNUMBER(AG16),ISNUMBER(AG17),AG16<>AG17),IF(AG16>AG17,AE16,AE17),"")) | AO18: M79 | Round of 32
A19: =Setup!$D$5 | C19: =IF('Knockout Pitch Map'!D20="","",'Knockout Pitch Map'!D20) | D19: Pick | AO19: =Setup!$D$13 | AQ19: =IF('Knockout Pitch Map'!AR20="","",'Knockout Pitch Map'!AR20) | AR19: Pick
A20: =Setup!$E$5 | C20: =IF('Knockout Pitch Map'!D21="","",'Knockout Pitch Map'!D21) | D20: =IF('Knockout Pitch Map'!B22="","",'Knockout Pitch Map'!B22) | AO20: =Setup!$E$13 | AQ20: =IF('Knockout Pitch Map'!AR21="","",'Knockout Pitch Map'!AR21) | AR20: =IF('Knockout Pitch Map'!AP22="","",'Knockout Pitch Map'!AP22)
A21: Winner | B21: =IF(D20<>"",D20,IF(AND(ISNUMBER(C19),ISNUMBER(C20),C19<>C20),IF(C19>C20,A19,A20),"")) | F21: M90 | Round of 16 | AJ21: M92 | Round of 16 | AO21: Winner | AP21: =IF(AR20<>"",AR20,IF(AND(ISNUMBER(AQ19),ISNUMBER(AQ20),AQ19<>AQ20),IF(AQ19>AQ20,AO19,AO20),""))
F22: =IF(OR(B21="",B21=0),"",B21) | H22: =IF('Knockout Pitch Map'!I23="","",'Knockout Pitch Map'!I23) | I22: Pick | AJ22: =IF(OR(AP21="",AP21=0),"",AP21) | AL22: =IF('Knockout Pitch Map'!AM23="","",'Knockout Pitch Map'!AM23) | AM22: Pick
F23: =IF(OR(B27="",B27=0),"",B27) | H23: =IF('Knockout Pitch Map'!I24="","",'Knockout Pitch Map'!I24) | I23: =IF('Knockout Pitch Map'!G25="","",'Knockout Pitch Map'!G25) | P23: Semi-finals | U23: Final | Z23: Semi-finals | AJ23: =IF(OR(AP27="",AP27=0),"",AP27) | AL23: =IF('Knockout Pitch Map'!AM24="","",'Knockout Pitch Map'!AM24) | AM23: =IF('Knockout Pitch Map'!AK25="","",'Knockout Pitch Map'!AK25)
A24: M75 | Round of 32 | F24: Winner | G24: =IF(I23<>"",I23,IF(AND(ISNUMBER(H22),ISNUMBER(H23),H22<>H23),IF(H22>H23,F22,F23),"")) | AJ24: Winner | AK24: =IF(AM23<>"",AM23,IF(AND(ISNUMBER(AL22),ISNUMBER(AL23),AL22<>AL23),IF(AL22>AL23,AJ22,AJ23),"")) | AO24: M80 | Round of 32
A25: =Setup!$D$6 | C25: =IF('Knockout Pitch Map'!D27="","",'Knockout Pitch Map'!D27) | D25: Pick | AO25: =Setup!$D$14 | AQ25: =IF('Knockout Pitch Map'!AR27="","",'Knockout Pitch Map'!AR27) | AR25: Pick
A26: =Setup!$E$6 | C26: =IF('Knockout Pitch Map'!D28="","",'Knockout Pitch Map'!D28) | D26: =IF('Knockout Pitch Map'!B29="","",'Knockout Pitch Map'!B29) | AO26: =Setup!$E$14 | AQ26: =IF('Knockout Pitch Map'!AR28="","",'Knockout Pitch Map'!AR28) | AR26: =IF('Knockout Pitch Map'!AP29="","",'Knockout Pitch Map'!AP29)
A27: Winner | B27: =IF(D26<>"",D26,IF(AND(ISNUMBER(C25),ISNUMBER(C26),C25<>C26),IF(C25>C26,A25,A26),"")) | P27: M101 | Semi-final | U27: M104 | Final | Z27: M102 | Semi-final | AO27: Winner | AP27: =IF(AR26<>"",AR26,IF(AND(ISNUMBER(AQ25),ISNUMBER(AQ26),AQ25<>AQ26),IF(AQ25>AQ26,AO25,AO26),""))
P28: =IF(OR(L18="",L18=0),"",L18) | R28: =IF('Knockout Pitch Map'!S30="","",'Knockout Pitch Map'!S30) | S28: Pick | U28: =IF(OR(Q30="",Q30=0),"",Q30) | W28: =IF('Knockout Pitch Map'!X26="","",'Knockout Pitch Map'!X26) | X28: Pick | Z28: =IF(OR(AF18="",AF18=0),"",AF18) | AB28: =IF('Knockout Pitch Map'!AC30="","",'Knockout Pitch Map'!AC30) | AC28: Pick
P29: =IF(OR(L42="",L42=0),"",L42) | R29: =IF('Knockout Pitch Map'!S31="","",'Knockout Pitch Map'!S31) | S29: =IF('Knockout Pitch Map'!Q32="","",'Knockout Pitch Map'!Q32) | U29: =IF(OR(AA30="",AA30=0),"",AA30) | W29: =IF('Knockout Pitch Map'!X27="","",'Knockout Pitch Map'!X27) | X29: =IF('Knockout Pitch Map'!V28="","",'Knockout Pitch Map'!V28) | Z29: =IF(OR(AF42="",AF42=0),"",AF42) | AB29: =IF('Knockout Pitch Map'!AC31="","",'Knockout Pitch Map'!AC31) | AC29: =IF('Knockout Pitch Map'!AA32="","",'Knockout Pitch Map'!AA32)
A30: M83 | Round of 32 | P30: Winner | Q30: =IF(S29<>"",S29,IF(AND(ISNUMBER(R28),ISNUMBER(R29),R28<>R29),IF(R28>R29,P28,P29),"")) | U30: Winner | V30: =IF(X29<>"",X29,IF(AND(ISNUMBER(W28),ISNUMBER(W29),W28<>W29),IF(W28>W29,U28,U29),"")) | Z30: Winner | AA30: =IF(AC29<>"",AC29,IF(AND(ISNUMBER(AB28),ISNUMBER(AB29),AB28<>AB29),IF(AB28>AB29,Z28,Z29),"")) | AO30: M86 | Round of 32
A31: =Setup!$D$7 | C31: =IF('Knockout Pitch Map'!D34="","",'Knockout Pitch Map'!D34) | D31: Pick | AO31: =Setup!$D$15 | AQ31: =IF('Knockout Pitch Map'!AR34="","",'Knockout Pitch Map'!AR34) | AR31: Pick
A32: =Setup!$E$7 | C32: =IF('Knockout Pitch Map'!D35="","",'Knockout Pitch Map'!D35) | D32: =IF('Knockout Pitch Map'!B36="","",'Knockout Pitch Map'!B36) | AO32: =Setup!$E$15 | AQ32: =IF('Knockout Pitch Map'!AR35="","",'Knockout Pitch Map'!AR35) | AR32: =IF('Knockout Pitch Map'!AP36="","",'Knockout Pitch Map'!AP36)
A33: Winner | B33: =IF(D32<>"",D32,IF(AND(ISNUMBER(C31),ISNUMBER(C32),C31<>C32),IF(C31>C32,A31,A32),"")) | F33: M93 | Round of 16 | AJ33: M95 | Round of 16 | AO33: Winner | AP33: =IF(AR32<>"",AR32,IF(AND(ISNUMBER(AQ31),ISNUMBER(AQ32),AQ31<>AQ32),IF(AQ31>AQ32,AO31,AO32),""))
F34: =IF(OR(B33="",B33=0),"",B33) | H34: =IF('Knockout Pitch Map'!I37="","",'Knockout Pitch Map'!I37) | I34: Pick | AJ34: =IF(OR(AP33="",AP33=0),"",AP33) | AL34: =IF('Knockout Pitch Map'!AM37="","",'Knockout Pitch Map'!AM37) | AM34: Pick
F35: =IF(OR(B39="",B39=0),"",B39) | H35: =IF('Knockout Pitch Map'!I38="","",'Knockout Pitch Map'!I38) | I35: =IF('Knockout Pitch Map'!G39="","",'Knockout Pitch Map'!G39) | AJ35: =IF(OR(AP39="",AP39=0),"",AP39) | AL35: =IF('Knockout Pitch Map'!AM38="","",'Knockout Pitch Map'!AM38) | AM35: =IF('Knockout Pitch Map'!AK39="","",'Knockout Pitch Map'!AK39)
A36: M84 | Round of 32 | F36: Winner | G36: =IF(I35<>"",I35,IF(AND(ISNUMBER(H34),ISNUMBER(H35),H34<>H35),IF(H34>H35,F34,F35),"")) | AJ36: Winner | AK36: =IF(AM35<>"",AM35,IF(AND(ISNUMBER(AL34),ISNUMBER(AL35),AL34<>AL35),IF(AL34>AL35,AJ34,AJ35),"")) | AO36: M88 | Round of 32
A37: =Setup!$D$8 | C37: =IF('Knockout Pitch Map'!D41="","",'Knockout Pitch Map'!D41) | D37: Pick | AO37: =Setup!$D$16 | AQ37: =IF('Knockout Pitch Map'!AR41="","",'Knockout Pitch Map'!AR41) | AR37: Pick
A38: =Setup!$E$8 | C38: =IF('Knockout Pitch Map'!D42="","",'Knockout Pitch Map'!D42) | D38: =IF('Knockout Pitch Map'!B43="","",'Knockout Pitch Map'!B43) | U38: M103 | Third place | AO38: =Setup!$E$16 | AQ38: =IF('Knockout Pitch Map'!AR42="","",'Knockout Pitch Map'!AR42) | AR38: =IF('Knockout Pitch Map'!AP43="","",'Knockout Pitch Map'!AP43)
A39: Winner | B39: =IF(D38<>"",D38,IF(AND(ISNUMBER(C37),ISNUMBER(C38),C37<>C38),IF(C37>C38,A37,A38),"")) | K39: M98 | Quarterfinal | U39: =IF(OR(Q30="",Q30=0),"",IF(Q30=P28,P29,IF(Q30=P29,P28,""))) | W39: =IF('Knockout Pitch Map'!X43="","",'Knockout Pitch Map'!X43) | X39: Pick | AE39: M100 | Quarterfinal | AO39: Winner | AP39: =IF(AR38<>"",AR38,IF(AND(ISNUMBER(AQ37),ISNUMBER(AQ38),AQ37<>AQ38),IF(AQ37>AQ38,AO37,AO38),""))
K40: =IF(OR(G36="",G36=0),"",G36) | M40: =IF('Knockout Pitch Map'!N44="","",'Knockout Pitch Map'!N44) | N40: Pick | U40: =IF(OR(AA30="",AA30=0),"",IF(AA30=Z28,Z29,IF(AA30=Z29,Z28,""))) | W40: =IF('Knockout Pitch Map'!X44="","",'Knockout Pitch Map'!X44) | X40: =IF('Knockout Pitch Map'!V45="","",'Knockout Pitch Map'!V45) | AE40: =IF(OR(AK36="",AK36=0),"",AK36) | AG40: =IF('Knockout Pitch Map'!AH44="","",'Knockout Pitch Map'!AH44) | AH40: Pick
K41: =IF(OR(G48="",G48=0),"",G48) | M41: =IF('Knockout Pitch Map'!N45="","",'Knockout Pitch Map'!N45) | N41: =IF('Knockout Pitch Map'!L46="","",'Knockout Pitch Map'!L46) | U41: Winner | V41: =IF(X40<>"",X40,IF(AND(ISNUMBER(W39),ISNUMBER(W40),W39<>W40),IF(W39>W40,U39,U40),"")) | AE41: =IF(OR(AK48="",AK48=0),"",AK48) | AG41: =IF('Knockout Pitch Map'!AH45="","",'Knockout Pitch Map'!AH45) | AH41: =IF('Knockout Pitch Map'!AF46="","",'Knockout Pitch Map'!AF46)
...

Sheet Match Results
A1: Group Fixtures and Results
A3: Match | B3: Date | C3: Group | D3: Team 1 | E3: Score 1 | F3: Score 2 | G3: Team 2 | H3: Status | I3: Winner | J3: Source URL | K3: Venue | L3: Date Key
A4: M001 | B4: 2026-06-11 | C4: A | D4: Mexico | E4: 2 | F4: 0 | G4: South Africa | H4: =IF(AND(ISNUMBER(E4),ISNUMBER(F4)),"Final","Scheduled") | I4: =IF(H4<>"Final","",IF(E4>F4,D4,IF(F4>E4,G4,"Draw"))) | J4: https://www.espn.com/soccer/story/_/id/48939282/2026-fifa-world-cup-fixtures-results-match-schedule-group-stage-knockout-rounds-bracket | K4: Mexico City Stadium | L4: 20260611
A5: M002 | B5: 2026-06-11 | C5: A | D5: Korea Republic | E5: 2 | F5: 1 | G5: Czechia | H5: =IF(AND(ISNUMBER(E5),ISNUMBER(F5)),"Final","Scheduled") | I5: =IF(H5<>"Final","",IF(E5>F5,D5,IF(F5>E5,G5,"Draw"))) | J5: https://www.espn.com/soccer/story/_/id/48939282/2026-fifa-world-cup-fixtures-results-match-schedule-group-stage-knockout-rounds-bracket | K5: Estadio Guadalajara | L5: 20260611
A6: M003 | B6: 2026-06-12 | C6: B | D6: Canada | E6: 1 | F6: 1 | G6: Bosnia and Herzegovina | H6: =IF(AND(ISNUMBER(E6),ISNUMBER(F6)),"Final","Scheduled") | I6: =IF(H6<>"Final","",IF(E6>F6,D6,IF(F6>E6,G6,"Draw"))) | J6: https://www.espn.com/soccer/story/_/id/48939282/2026-fifa-world-cup-fixtures-results-match-schedule-group-stage-knockout-rounds-bracket | K6: Toronto Stadium | L6: 20260612
A7: M004 | B7: 2026-06-12 | C7: D | D7: USA | E7: 4 | F7: 1 | G7: Paraguay | H7: =IF(AND(ISNUMBER(E7),ISNUMBER(F7)),"Final","Scheduled") | I7: =IF(H7<>"Final","",IF(E7>F7,D7,IF(F7>E7,G7,"Draw"))) | J7: https://www.espn.com/soccer/story/_/id/48939282/2026-fifa-world-cup-fixtures-results-match-schedule-group-stage-knockout-rounds-bracket | K7: Los Angeles Stadium | L7: 20260612
A8: M005 | B8: 2026-06-13 | C8: B | D8: Switzerland | E8: 1 | F8: 1 | G8: Qatar | H8: =IF(AND(ISNUMBER(E8),ISNUMBER(F8)),"Final","Scheduled") | I8: =IF(H8<>"Final","",IF(E8>F8,D8,IF(F8>E8,G8,"Draw"))) | J8: https://www.espn.com/soccer/story/_/id/48939282/2026-fifa-world-cup-fixtures-results-match-schedule-group-stage-knockout-rounds-bracket | K8: San Francisco Bay Area Stadium | L8: 20260613
A9: M006 | B9: 2026-06-13 | C9: C | D9: Brazil | E9: 1 | F9: 1 | G9: Morocco | H9: =IF(AND(ISNUMBER(E9),ISNUMBER(F9)),"Final","Scheduled") | I9: =IF(H9<>"Final","",IF(E9>F9,D9,IF(F9>E9,G9,"Draw"))) | J9: https://www.espn.com/soccer/story/_/id/48939282/2026-fifa-world-cup-fixtures-results-match-schedule-group-stage-knockout-rounds-bracket | K9: New York New Jersey Stadium | L9: 20260613
A10: M007 | B10: 2026-06-13 | C10: C | D10: Scotland | E10: 1 | F10: 0 | G10: Haiti | H10: =IF(AND(ISNUMBER(E10),ISNUMBER(F10)),"Final","Scheduled") | I10: =IF(H10<>"Final","",IF(E10>F10,D10,IF(F10>E10,G10,"Draw"))) | J10: https://www.espn.com/soccer/story/_/id/48939282/2026-fifa-world-cup-fixtures-results-match-schedule-group-stage-knockout-rounds-bracket | K10: Boston Stadium | L10: 20260613
A11: M008 | B11: 2026-06-13 | C11: D | D11: Australia | E11: 2 | F11: 0 | G11: Türkiye | H11: =IF(AND(ISNUMBER(E11),ISNUMBER(F11)),"Final","Scheduled") | I11: =IF(H11<>"Final","",IF(E11>F11,D11,IF(F11>E11,G11,"Draw"))) | J11: https://www.espn.com/soccer/story/_/id/48939282/2026-fifa-world-cup-fixtures-results-match-schedule-group-stage-knockout-rounds-bracket | K11: BC Place Vancouver | L11: 20260613
A12: M009 | B12: 2026-06-14 | C12: E | D12: Germany | E12: 7 | F12: 1 | G12: Curaçao | H12: =IF(AND(ISNUMBER(E12),ISNUMBER(F12)),"Final","Scheduled") | I12: =IF(H12<>"Final","",IF(E12>F12,D12,IF(F12>E12,G12,"Draw"))) | J12: https://www.espn.com/soccer/story/_/id/48939282/2026-fifa-world-cup-fixtures-results-match-schedule-group-stage-knockout-rounds-bracket | K12: Houston Stadium | L12: 20260614
A13: M010 | B13: 2026-06-14 | C13: F | D13: Netherlands | E13: 2 | F13: 2 | G13: Japan | H13: =IF(AND(ISNUMBER(E13),ISNUMBER(F13)),"Final","Scheduled") | I13: =IF(H13<>"Final","",IF(E13>F13,D13,IF(F13>E13,G13,"Draw"))) | J13: https://www.espn.com/soccer/story/_/id/48939282/2026-fifa-world-cup-fixtures-results-match-schedule-group-stage-knockout-rounds-bracket | K13: Dallas Stadium | L13: 20260614
A14: M011 | B14: 2026-06-14 | C14: E | D14: Côte d'Ivoire | E14: 1 | F14: 0 | G14: Ecuador | H14: =IF(AND(ISNUMBER(E14),ISNUMBER(F14)),"Final","Scheduled") | I14: =IF(H14<>"Final","",IF(E14>F14,D14,IF(F14>E14,G14,"Draw"))) | J14: https://www.espn.com/soccer/story/_/id/48939282/2026-fifa-world-cup-fixtures-results-match-schedule-group-stage-knockout-rounds-bracket | K14: Philadelphia Stadium | L14: 20260614
A15: M012 | B15: 2026-06-14 | C15: F | D15: Sweden | E15: 5 | F15: 1 | G15: Tunisia | H15: =IF(AND(ISNUMBER(E15),ISNUMBER(F15)),"Final","Scheduled") | I15: =IF(H15<>"Final","",IF(E15>F15,D15,IF(F15>E15,G15,"Draw"))) | J15: https://www.espn.com/soccer/story/_/id/48939282/2026-fifa-world-cup-fixtures-results-match-schedule-group-stage-knockout-rounds-bracket | K15: Estadio Monterrey | L15: 20260614
... A19: M016 | B19: 2026-06-15 | C19: G | D19: IR Iran | E19: 2 | F19: 2 | G19: New Zealand | H19: =IF(AND(ISNUMBER(E19),ISNUMBER(F19)),"Final","Scheduled") | I19: =IF(H19<>"Final","",IF(E19>F19,D19,IF(F19>E19,G19,"Draw"))) | J19: https://www.espn.com/soccer/story/_/id/48939282/2026-fifa-world-cup-fixtures-results-match-schedule-group-stage-knockout-rounds-bracket | K19: Los Angeles Stadium | L19: 20260615
A20: M017 | B20: 2026-06-16 | C20: I | D20: France | G20: Senegal | H20: =IF(AND(ISNUMBER(E20),ISNUMBER(F20)),"Final","Scheduled") | I20: =IF(H20<>"Final","",IF(E20>F20,D20,IF(F20>E20,G20,"Draw"))) | J20: https://www.espn.com/soccer/story/_/id/48939282/2026-fifa-world-cup-fixtures-results-match-schedule-group-stage-knockout-rounds-bracket | K20: New York New Jersey Stadium | L20: 20260616
A21: M018 | B21: 2026-06-16 | C21: I | D21: Iraq | G21: Norway | H21: =IF(AND(ISNUMBER(E21),ISNUMBER(F21)),"Final","Scheduled") | I21: =IF(H21<>"Final","",IF(E21>F21,D21,IF(F21>E21,G21,"Draw"))) | J21: https://www.espn.com/soccer/story/_/id/48939282/2026-fifa-world-cup-fixtures-results-match-schedule-group-stage-knockout-rounds-bracket | K21: Boston Stadium | L21: 20260616
A22: M019 | B22: 2026-06-16 | C22: J | D22: Argentina | G22: Algeria | H22: =IF(AND(ISNUMBER(E22),ISNUMBER(F22)),"Final","Scheduled") | I22: =IF(H22<>"Final","",IF(E22>F22,D22,IF(F22>E22,G22,"Draw"))) | J22: https://www.espn.com/soccer/story/_/id/48939282/2026-fifa-world-cup-fixtures-results-match-schedule-group-stage-knockout-rounds-bracket | K22: Kansas City Stadium | L22: 20260616
A23: M020 | B23: 2026-06-16 | C23: J | D23: Austria | G23: Jordan | H23: =IF(AND(ISNUMBER(E23),ISNUMBER(F23)),"Final","Scheduled") | I23: =IF(H23<>"Final","",IF(E23>F23,D23,IF(F23>E23,G23,"Draw"))) | J23: https://www.espn.com/soccer/story/_/id/48939282/2026-fifa-world-cup-fixtures-results-match-schedule-group-stage-knockout-rounds-bracket | K23: San Francisco Bay Area Stadium | L23: 20260616
A24: M021 | B24: 2026-06-17 | C24: K | D24: Portugal | G24: Congo DR | H24: =IF(AND(ISNUMBER(E24),ISNUMBER(F24)),"Final","Scheduled") | I24: =IF(H24<>"Final","",IF(E24>F24,D24,IF(F24>E24,G24,"Draw"))) | J24: https://www.espn.com/soccer/story/_/id/48939282/2026-fifa-world-cup-fixtures-results-match-schedule-group-stage-knockout-rounds-bracket | K24: Houston Stadium | L24: 20260617
A25: M022 | B25: 2026-06-17 | C25: L | D25: England | G25: Croatia | H25: =IF(AND(ISNUMBER(E25),ISNUMBER(F25)),"Final","Scheduled") | I25: =IF(H25<>"Final","",IF(E25>F25,D25,IF(F25>E25,G25,"Draw"))) | J25: https://www.espn.com/soccer/story/_/id/48939282/2026-fifa-world-cup-fixtures-results-match-schedule-group-stage-knockout-rounds-bracket | K25: Dallas Stadium | L25: 20260617
A26: M023 | B26: 2026-06-17 | C26: L | D26: Ghana | G26: Panama | H26: =IF(AND(ISNUMBER(E26),ISNUMBER(F26)),"Final","Scheduled") | I26: =IF(H26<>"Final","",IF(E26>F26,D26,IF(F26>E26,G26,"Draw"))) | J26: https://www.espn.com/soccer/story/_/id/48939282/2026-fifa-world-cup-fixtures-results-match-schedule-group-stage-knockout-rounds-bracket | K26: Toronto Stadium | L26: 20260617
A27: M024 | B27: 2026-06-17 | C27: K | D27: Uzbekistan | G27: Colombia | H27: =IF(AND(ISNUMBER(E27),ISNUMBER(F27)),"Final","Scheduled") | I27: =IF(H27<>"Final","",IF(E27>F27,D27,IF(F27>E27,G27,"Draw"))) | J27: https://www.espn.com/soccer/story/_/id/48939282/2026-fifa-world-cup-fixtures-results-match-schedule-group-stage-knockout-rounds-bracket | K27: Mexico City Stadium | L27: 20260617
A28: M025 | B28: 2026-06-18 | C28: A | D28: Czechia | G28: South Africa | H28: =IF(AND(ISNUMBER(E28),ISNUMBER(F28)),"Final","Scheduled") | I28: =IF(H28<>"Final","",IF(E28>F28,D28,IF(F28>E28,G28,"Draw"))) | J28: https://www.espn.com/soccer/story/_/id/48939282/2026-fifa-world-cup-fixtures-results-match-schedule-group-stage-knockout-rounds-bracket | K28: Atlanta Stadium | L28: 20260618
A29: M026 | B29: 2026-06-18 | C29: B | D29: Switzerland | G29: Bosnia and Herzegovina | H29: =IF(AND(ISNUMBER(E29),ISNUMBER(F29)),"Final","Scheduled") | I29: =IF(H29<>"Final","",IF(E29>F29,D29,IF(F29>E29,G29,"Draw"))) | J29: https://www.espn.com/soccer/story/_/id/48939282/2026-fifa-world-cup-fixtures-results-match-schedule-group-stage-knockout-rounds-bracket | K29: Los Angeles Stadium | L29: 20260618
A30: M027 | B30: 2026-06-18 | C30: B | D30: Canada | G30: Qatar | H30: =IF(AND(ISNUMBER(E30),ISNUMBER(F30)),"Final","Scheduled") | I30: =IF(H30<>"Final","",IF(E30>F30,D30,IF(F30>E30,G30,"Draw"))) | J30: https://www.espn.com/soccer/story/_/id/48939282/2026-fifa-world-cup-fixtures-results-match-schedule-group-stage-knockout-rounds-bracket | K30: BC Place Vancouver | L30: 20260618
A31: M028 | B31: 2026-06-18 | C31: A | D31: Mexico | G31: Korea Republic | H31: =IF(AND(ISNUMBER(E31),ISNUMBER(F31)),"Final","Scheduled") | I31: =IF(H31<>"Final","",IF(E31>F31,D31,IF(F31>E31,G31,"Draw"))) | J31: https://www.espn.com/soccer/story/_/id/48939282/2026-fifa-world-cup-fixtures-results-match-schedule-group-stage-knockout-rounds-bracket | K31: Estadio Guadalajara | L31: 20260618
... A75: M072 | B75: 2026-06-27 | C75: J | D75: Jordan | G75: Argentina | H75: =IF(AND(ISNUMBER(E75),ISNUMBER(F75)),"Final","Scheduled") | I75: =IF(H75<>"Final","",IF(E75>F75,D75,IF(F75>E75,G75,"Draw"))) | J75: https://www.espn.com/soccer/story/_/id/48939282/2026-fifa-world-cup-fixtures-results-match-schedule-group-stage-knockout-rounds-bracket | K75: Dallas Stadium | L75: 20260627

Sheet Annex C
A1: Option | B1: 1A | C1: 1B | D1: 1D | E1: 1E | F1: 1G | G1: 1I | H1: 1K | I1: 1L | J1: Combo
A2: 1 | B2: 3E | C2: 3J | D2: 3I | E2: 3F | F2: 3H | G2: 3G | H2: 3L | I2: 3K | J2: EFGHIJKL
A3: 2 | B3: 3H | C3: 3G | D3: 3I | E3: 3D | F3: 3J | G3: 3F | H3: 3L | I3: 3K | J3: DFGHIJKL
A4: 3 | B4: 3E | C4: 3J | D4: 3I | E4: 3D | F4: 3H | G4: 3G | H4: 3L | I4: 3K | J4: DEGHIJKL
A5: 4 | B5: 3E | C5: 3J | D5: 3I | E5: 3D | F5: 3H | G5: 3F | H5: 3L | I5: 3K | J5: DEFHIJKL
